Workbook

Sheet Dashboard
B2: OBU Autonomous Racing — Budget Tracker 2024/25
B3: Formula SAE Cost Compliance Report | Adapted from FIA Financial Regulations Framework
B5: Total Budget | C5: Total Actual | D5: Headroom | E5: Cap Utilisation
B6: =Data!E48 -> 38680 | C6: =Data!F48 -> 41070 | D6: =Data!E48-Data!F48 -> -2390 | E6: =Data!F48/Data!E48 -> 1.061789
B7: Season target spend | C7: Year-to-date spend | D7: Remaining budget | E7: % of budget consumed
B9: ▸ CATEGORY BREAKDOWN
B10: FIA-Mapped Category | C10: Budget (£) | D10: Actual (£) | E10: Variance (£) | F10: RAG | G10: Root Cause Summary | H10: Corrective Action Summary
B11: Chassis & Aero Components | C11: =Data!E3 -> 11750 | D11: =Data!F3 -> 14200 | E11: =D11-C11 -> 2450 | F11: =IF(C11=0,"N/A",IF((D11-C11)/C11>0.05,"RED",IF((D11-C11)/C11>0,"AMBER","GREEN"))) -> RED | G11: Largest variance: Monocoque / frame materials (CFRP pre-preg, core, consumable... | H11: Introduce mandatory layup sign-off checklist. Maintain 10% CFRP material contingency....
B12: Drivetrain & Suspension | C12: =Data!E9 -> 9200 | D12: =Data!F9 -> 8750 | E12: =D12-C12 -> -450 | F12: =IF(C12=0,"N/A",IF((D12-C12)/C12>0.05,"RED",IF((D12-C12)/C12>0,"AMBER","GREEN"))) -> GREEN | G12: Largest variance: Steering rack, column & quick-release hub... | H12: Qualify backup suppliers for all safety-critical steering components....
B13: Manufacturing & Workshop | C13: =Data!E16 -> 6800 | D13: =Data!F16 -> 7600 | E13: =D13-C13 -> 800 | F13: =IF(C13=0,"N/A",IF((D13-C13)/C13>0.05,"RED",IF((D13-C13)/C13>0,"AMBER","GREEN"))) -> RED | G13: Largest variance: CNC machine hire (uprights, brackets, pedal box — external s... | H13: Lock CNC geometry sign-off to Week 8. Add £300 rework contingency to CNC budget....
B14: Team Training & Development | C14: =Data!E23 -> 1100 | D14: =Data!F23 -> 1060 | E14: =D14-C14 -> -40 | F14: =IF(C14=0,"N/A",IF((D14-C14)/C14>0.05,"RED",IF((D14-C14)/C14>0,"AMBER","GREEN"))) -> GREEN | G14: Largest variance: Coursera team subscriptions (CFD, FEA, data analysis — 4 mem... | H14: Extend to 8 members in 2025/26. Require completion certificate as condition of membership....
B15: Travel & Competition Logistics | C15: =Data!E28 -> 5200 | D15: =Data!F28 -> 5410 | E15: =D15-C15 -> 210 | F15: =IF(C15=0,"N/A",IF((D15-C15)/C15>0.05,"RED",IF((D15-C15)/C15>0,"AMBER","GREEN"))) -> AMBER | G15: Largest variance: Van hire — Silverstone FS UK (3-day event, 7-seat + trailer)... | H15: Book van minimum 4 months in advance. Obtain 3 quotes. Consider trailer-share agreement....
B16: Testing & Shakedown | C16: =Data!E36 -> 3380 | D16: =Data!F36 -> 3100 | E16: =D16-C16 -> -280 | F16: =IF(C16=0,"N/A",IF((D16-C16)/C16>0.05,"RED",IF((D16-C16)/C16>0,"AMBER","GREEN"))) -> GREEN | G16: Largest variance: Circuit hire — Silverstone MIRA test day (1 day, mid-season ... | H16: Maintain consortium membership to retain access to discounted circuit testing....
B17: Equipment & Tooling | C17: =Data!E42 -> 1250 | D17: =Data!F42 -> 950 | E17: =D17-C17 -> -300 | F17: =IF(C17=0,"N/A",IF((D17-C17)/C17>0.05,"RED",IF((D17-C17)/C17>0,"AMBER","GREEN"))) -> GREEN | G17: Largest variance: Oscilloscope & multimeter (borrowed from university Elec Eng... | H17: Renew loan agreement annually. Offer reciprocal support (e.g. data analysis help)....
B18: TOTAL | C18: =SUM(C11:C17) -> 38680 | D18: =SUM(D11:D17) -> 41070 | E18: =D18-C18 -> 2390
B20: ▸ COMPLIANCE SUMMARY
B21: Total Gross Overspend | C21: =SUMIF(E11:E17,">0",E11:E17) -> 3460
B22: Total Gross Savings | C22: =ABS(SUMIF(E11:E17,"<0",E11:E17)) -> 1070
B23: Net Variance | C23: =D18-C18 -> 2390
B24: Categories RED | C24: =COUNTIF(F11:F17,"RED") -> 2
B25: Categories AMBER | C25: =COUNTIF(F11:F17,"AMBER") -> 1
B26: Categories GREEN | C26: =COUNTIF(F11:F17,"GREEN") -> 4
B28: Prepared by: Wolfgang Guio | OBU Autonomous Racing | 2024/25 Season | Simulated data for portfolio purposes.

Sheet Data
B1: DATA INPUT SHEET — Edit blue cells only | Sub-component detail feeds category totals automatically
A2: Cat | B2: # | C2: Sub-Component / Line Item | D2: FIA Category | E2: Budget (£) | F2: Actual (£) | G2: RAG | H2: Root Cause | I2: Corrective Action
A3: CH | C3: ▸ Chassis & Aero Components | E3: =SUM(E4:E8) -> 11750 | F3: =SUM(F4:F8) -> 14200 | G3: =F3-E3 -> 2450 | H3: =IF(E3=0,0,(F3-E3)/E3) -> 0.20851064 | I3: =IF(H3>0.05,"RED",IF(H3>0,"AMBER","GREEN")) -> RED
A4: CH | B4: 1 | C4: Monocoque / frame materials (CFRP pre-preg, core, consumables) | D4: Chassis & Aerodynamic Parts | E4: 4800 | F4: 6200 | G4: =IF(E4=0,"N/A",IF((F4-E4)/E4>0.05,"RED",IF((F4-E4)/E4>0,"AMBER","GREEN"))) -> RED | H4: Layup failure in Week 6 required full re-lamination of monocoque tub. Additional pre-preg and vacuum bagging consumables added £1,400 above budget. | I4: Introduce mandatory layup sign-off checklist. Maintain 10% CFRP material contingency.
A5: CH | B5: 2 | C5: Aero package (front wing, diffuser, sidepods — outsourced laser cut & waterjet) | D5: Chassis & Aerodynamic Parts | E5: 3200 | F5: 4500 | G5: =IF(E5=0,"N/A",IF((F5-E5)/E5>0.05,"RED",IF((F5-E5)/E5>0,"AMBER","GREEN"))) -> RED | H5: Post-CFD correlation required endplate and diffuser geometry revision. Two additional outsourced laser-cut iterations added £1,300 in unbudgeted parts cost. | I5: Freeze aero geometry at CFD sign-off gate (Week 4). Add aero iteration cost reserve.
A6: CH | B6: 3 | C6: Bodywork & fairings (GRP moulds, paint, fixings) | D6: Chassis & Aerodynamic Parts | E6: 2100 | F6: 1950 | G6: =IF(E6=0,"N/A",IF((F6-E6)/E6>0.05,"RED",IF((F6-E6)/E6>0,"AMBER","GREEN"))) -> GREEN | H6: Bodywork produced in-house with university mould stock. Minor underspend on fixings. | I6: Continue in-house production. Expand mould library for 2025/26 aero package.
A7: CH | B7: 4 | C7: Structural adhesives, fasteners & chassis consumables | D7: Chassis & Aerodynamic Parts | E7: 900 | F7: 820 | G7: =IF(E7=0,"N/A",IF((F7-E7)/E7>0.05,"RED",IF((F7-E7)/E7>0,"AMBER","GREEN"))) -> GREEN | H7: Bulk adhesive order shared with another university team reduced per-unit cost. | I7: Formalise inter-team procurement agreements for shared consumables.
A8: CH | B8: 5 | C8: Safety cell / roll hoop (steel, welding materials) | D8: Chassis & Aerodynamic Parts | E8: 750 | F8: 730 | G8: =IF(E8=0,"N/A",IF((F8-E8)/E8>0.05,"RED",IF((F8-E8)/E8>0,"AMBER","GREEN"))) -> GREEN | H8: Roll hoop fabricated in-house by experienced welding lead. On budget. | I8: Document fabrication procedure for knowledge transfer to next year's team.
A9: DS | C9: ▸ Drivetrain & Suspension | E9: =SUM(E10:E15) -> 9200 | F9: =SUM(F10:F15) -> 8750 | G9: =F9-E9 -> -450 | H9: =IF(E9=0,0,(F9-E9)/E9) -> -0.048913043 | I9: =IF(H9>0.05,"RED",IF(H9>0,"AMBER","GREEN")) -> GREEN
A10: DS | B10: 1 | C10: Engine & intake (Yamaha YZF-R6 sourced second-hand, seals, gaskets) | D10: Listed Parts (Gearbox & Suspension) | E10: 2800 | F10: 2650 | G10: =IF(E10=0,"N/A",IF((F10-E10)/E10>0.05,"RED",IF((F10-E10)/E10>0,"AMBER","GREEN"))) -> GREEN | H10: Second-hand engine sourced for £200 below budget. Gasket kit bought in bulk. | I10: Maintain second-hand engine sourcing strategy. Document engine spec for next season.
A11: DS | B11: 2 | C11: Gearbox internals & chain drive (sprockets, chain, bearings) | D11: Listed Parts (Gearbox & Suspension) | E11: 1400 | F11: 1280 | G11: =IF(E11=0,"N/A",IF((F11-E11)/E11>0.05,"RED",IF((F11-E11)/E11>0,"AMBER","GREEN"))) -> GREEN | H11: Chain and sprocket sourced via sponsor discount (15% off list price). | I11: Expand sponsor framework to include drivetrain consumables category.
A12: DS | B12: 3 | C12: Suspension wishbones & uprights (in-house CNC aluminium) | D12: Listed Parts (Gearbox & Suspension) | E12: 1800 | F12: 1600 | G12: =IF(E12=0,"N/A",IF((F12-E12)/E12>0.05,"RED",IF((F12-E12)/E12>0,"AMBER","GREEN"))) -> GREEN | H12: Wishbone brackets CNC-machined in-house, saving £320 vs outsource quote. | I12: Document in-house vs outsource cost matrix. Apply model to other machined parts.
A13: DS | B13: 4 | C13: Steering rack, column & quick-release hub | D13: Listed Parts (Gearbox & Suspension) | E13: 950 | F13: 1050 | G13: =IF(E13=0,"N/A",IF((F13-E13)/E13>0.05,"RED",IF((F13-E13)/E13>0,"AMBER","GREEN"))) -> RED | H13: Quick-release hub sourced from new supplier at higher price after original supplier stock-out. | I13: Qualify backup suppliers for all safety-critical steering components.
A14: DS | B14: 5 | C14: Wheel hubs, brake discs & callipers | D14: Listed Parts (Gearbox & Suspension) | E14: 1400 | F14: 1350 | G14: =IF(E14=0,"N/A",IF((F14-E14)/E14>0.05,"RED",IF((F14-E14)/E14>0,"AMBER","GREEN"))) -> GREEN | H14: Brake discs purchased as part of group buy with two other FSAE teams. | I14: Continue group-buy strategy for standardised brake components.
A15: DS | B15: 6 | C15: Differential & CV joints | D15: Listed Parts (Gearbox & Suspension) | E15: 850 | F15: 820 | G15: =IF(E15=0,"N/A",IF((F15-E15)/E15>0.05,"RED",IF((F15-E15)/E15>0,"AMBER","GREEN"))) -> GREEN | H15: CV joints reused from prior season car after inspection. Differential on budget. | I15: Inspect and catalogue reusable drivetrain components at season end each year.
A16: MF | C16: ▸ Manufacturing & Workshop | E16: =SUM(E17:E22) -> 6800 | F16: =SUM(F17:F22) -> 7600 | G16: =F16-E16 -> 800 | H16: =IF(E16=0,0,(F16-E16)/E16) -> 0.11764706 | I16: =IF(H16>0.05,"RED",IF(H16>0,"AMBER","GREEN")) -> RED
A17: MF | B17: 1 | C17: CNC machine hire (uprights, brackets, pedal box — external supplier) | D17: Manufacturing Operations | E17: 2800 | F17: 3300 | G17: =IF(E17=0,"N/A",IF((F17-E17)/E17>0.05,"RED",IF((F17-E17)/E17>0,"AMBER","GREEN"))) -> RED | H17: Unplanned rework of upright geometry after simulation data review required two additional CNC sessions, adding £500 to hire cost. | I17: Lock CNC geometry sign-off to Week 8. Add £300 rework contingency to CNC budget.
A18: MF | B18: 2 | C18: 3D printing consumables (resin, FDM filament, post-processing) | D18: Manufacturing Operations | E18: 1200 | F18: 1500 | G18: =IF(E18=0,"N/A",IF((F18-E18)/E18>0.05,"RED",IF((F18-E18)/E18>0,"AMBER","GREEN"))) -> RED | H18: Resin prices rose 18% mid-season vs budget assumption. Additional iterations on brake duct prototypes added £150 in filament spend. | I18: Review consumable pricing quarterly. Set per-part print approval threshold.
A19: MF | B19: 3 | C19: Welding materials & gas (MIG/TIG — frame, exhaust, mounts) | D19: Manufacturing Operations | E19: 850 | F19: 820 | G19: =IF(E19=0,"N/A",IF((F19-E19)/E19>0.05,"RED",IF((F19-E19)/E19>0,"AMBER","GREEN"))) -> GREEN | H19: Gas consumption below estimate due to efficient joint preparation by welding lead. | I19: Record gas usage per assembly stage for improved future budgeting.
A20: MF | B20: 4 | C20: Workshop consumables (cutting discs, PPE, lubricants, sandpaper) | D20: Manufacturing Operations | E20: 600 | F20: 580 | G20: =IF(E20=0,"N/A",IF((F20-E20)/E20>0.05,"RED",IF((F20-E20)/E20>0,"AMBER","GREEN"))) -> GREEN | H20: Bulk PPE order at start of season reduced per-item cost. On budget. | I20: Maintain bulk ordering strategy at season start.
A21: MF | B21: 5 | C21: Outsourced waterjet & laser cutting (aero brackets, plates) | D21: Manufacturing Operations | E21: 950 | F21: 980 | G21: =IF(E21=0,"N/A",IF((F21-E21)/E21>0.05,"RED",IF((F21-E21)/E21>0,"AMBER","GREEN"))) -> AMBER | H21: Minor overspend on one additional laser-cut bracket iteration. Within tolerance. | I21: Include one revision iteration in outsource budget estimate by default.
A22: MF | B22: 6 | C22: Surface finish, anodising & powder coating (external) | D22: Manufacturing Operations | E22: 400 | F22: 420 | G22: =IF(E22=0,"N/A",IF((F22-E22)/E22>0.05,"RED",IF((F22-E22)/E22>0,"AMBER","GREEN"))) -> AMBER | H22: Anodising of uprights and hubs on budget. Slight overspend on powder coating. | I22: Combine parts batches to reduce per-run powder coat cost.
A23: TR | C23: ▸ Team Training & Development | E23: =SUM(E24:E27) -> 1100 | F23: =SUM(F24:F27) -> 1060 | G23: =F23-E23 -> -40 | H23: =IF(E23=0,0,(F23-E23)/E23) -> -0.036363636 | I23: =IF(H23>0.05,"RED",IF(H23>0,"AMBER","GREEN")) -> GREEN
A24: TR | B24: 1 | C24: Coursera team subscriptions (CFD, FEA, data analysis — 24 members × 6 months) | D24: Personnel (Capped Employees) | E24: 480 | F24: 480 | G24: =IF(E24=0,"N/A",IF((F24-E24)/E24>0.05,"RED",IF((F24-E24)/E24>0,"AMBER","GREEN"))) -> GREEN | H24: Four team leads subscribed to Coursera for 6 months (£20/month each). Courses completed: FEA with Ansys, Python for Data Science, Vehicle Dynamics Fundamentals. | I24: Extend to 8 members in 2025/26. Require completion certificate as condition of membership.
A25: TR | B25: 2 | C25: Udemy licences (individual courses) | D25: Personnel (Capped Employees) | E25: 180 | F25: 165 | G25: =IF(E25=0,"N/A",IF((F25-E25)/E25>0.05,"RED",IF((F25-E25)/E25>0,"AMBER","GREEN"))) -> GREEN | H25: 7 targeted Udemy courses purchased at sale prices (avg £14 vs £25 list). Covered SolidWorks advanced surfacing, MATLAB/Simulink intro, and OpenFOAM basics. | I25: Monitor Udemy sale cycles (typically Nov and Jan). Pre-identify courses in September.
A26: TR | B26: 3 | C26: LinkedIn Learning team access (project management, presenting to sponsors) | D26: Personnel (Capped Employees) | E26: 120 | F26: 120 | G26: =IF(E26=0,"N/A",IF((F26-E26)/E26>0.05,"RED",IF((F26-E26)/E26>0,"AMBER","GREEN"))) -> GREEN | H26: University provided subsidised LinkedIn Learning access for 10 members. Sponsor presentation and project management modules completed by all senior members. | I26: Leverage university learning platform deal annually. Add technical writing module.
A27: TR | B27: 5 | C27: Internal workshop materials (printed guides, whiteboard supplies) | D27: Personnel (Capped Employees) | E27: 320 | F27: 295 | G27: =IF(E27=0,"N/A",IF((F27-E27)/E27>0.05,"RED",IF((F27-E27)/E27>0,"AMBER","GREEN"))) -> GREEN | H27: University printer used for most materials at subsidised cost. Minor underspend. | I27: Continue using university printing facilities. Explore digital-first workshop format.
A28: TL | C28: ▸ Travel & Competition Logistics | E28: =SUM(E29:E35) -> 5200 | F28: =SUM(F29:F35) -> 5410 | G28: =F28-E28 -> 210 | H28: =IF(E28=0,0,(F28-E28)/E28) -> 0.040384615 | I28: =IF(H28>0.05,"RED",IF(H28>0,"AMBER","GREEN")) -> AMBER
A29: TL | B29: 1 | C29: Van hire — Silverstone FS UK (3-day event, 7-seat + trailer) | D29: Travel & Freight | E29: 900 | F29: 1080 | G29: =IF(E29=0,"N/A",IF((F29-E29)/E29>0.05,"RED",IF((F29-E29)/E29>0,"AMBER","GREEN"))) -> RED | H29: Van hire rate increased 15% vs prior year booking. No early reservation made. | I29: Book van minimum 4 months in advance. Obtain 3 quotes. Consider trailer-share agreement.
A30: TL | B30: 2 | C30: Van hire — FS Germany, Hockenheim (4-day, cross-channel) | D30: Travel & Freight | E30: 1400 | F30: 1300 | G30: =IF(E30=0,"N/A",IF((F30-E30)/E30>0.05,"RED",IF((F30-E30)/E30>0,"AMBER","GREEN"))) -> GREEN | H30: Cross-channel ferry discount granted £100. Diesel cost higher than budgeted. | I30: Include 10% fuel and ferry contingency for all European events.
A31: TL | B31: 3 | C31: Fuel costs (both events combined) | D31: Travel & Freight | E31: 600 | F31: 590 | G31: =IF(E31=0,"N/A",IF((F31-E31)/E31>0.05,"RED",IF((F31-E31)/E31>0,"AMBER","GREEN"))) -> GREEN | H31: Diesel prices rose significantly between budget-setting (Oct) and event dates (Jun/Jul). £180 overspend vs estimate. | I31: Index fuel budget to HMRC advisory rates published in April each year.
A32: TL | B32: 4 | C32: Team accommodation — FS UK (4 members × 2 nights) | D32: Travel & Freight | E32: 640 | F32: 620 | G32: =IF(E32=0,"N/A",IF((F32-E32)/E32>0.05,"RED",IF((F32-E32)/E32>0,"AMBER","GREEN"))) -> GREEN | H32: AirBnB near circuit booked early. Split cost with partner team for one night. | I32: Continue early accommodation booking. Explore campsite options to further reduce cost.
A33: TL | B33: 5 | C33: Team accommodation — FS Germany (4 members × 3 nights) | D33: Travel & Freight | E33: 880 | F33: 870 | G33: =IF(E33=0,"N/A",IF((F33-E33)/E33>0.05,"RED",IF((F33-E33)/E33>0,"AMBER","GREEN"))) -> GREEN | H33: Hostel booked 3 months in advance at student rate. On budget. | I33: Maintain advance booking strategy for European events.
A34: TL | B34: 6 | C34: Competition entry fees (FS UK + FS Germany) | D34: Travel & Freight | E34: 480 | F34: 480 | G34: =IF(E34=0,"N/A",IF((F34-E34)/E34>0.05,"RED",IF((F34-E34)/E34>0,"AMBER","GREEN"))) -> GREEN | H34: Entry fees paid at published rates. No change from prior year. | I34: Budget at published rates. Apply for FSAE scholarship fund to offset entry costs.
A35: TL | B35: 7 | C35: Freight / parts shipping (urgent courier for replacement parts mid-event) | D35: Travel & Freight | E35: 300 | F35: 470 | G35: =IF(E35=0,"N/A",IF((F35-E35)/E35>0.05,"RED",IF((F35-E35)/E35>0,"AMBER","GREEN"))) -> RED | H35: Upright failure at FS UK required emergency overnight courier of replacement part. £170 above budget. | I35: Carry a spares kit for high-risk components. Build £200 emergency freight reserve.
A36: TS | C36: ▸ Testing & Shakedown | E36: =SUM(E37:E41) -> 3380 | F36: =SUM(F37:F41) -> 3100 | G36: =F36-E36 -> -280 | H36: =IF(E36=0,0,(F36-E36)/E36) -> -0.082840237 | I36: =IF(H36>0.05,"RED",IF(H36>0,"AMBER","GREEN")) -> GREEN
A37: TS | B37: 1 | C37: Circuit hire — Bicester (2 days, pre-season shakedown) | D37: Testing & Track Operations | E37: 1400 | F37: 1200 | G37: =IF(E37=0,"N/A",IF((F37-E37)/E37>0.05,"RED",IF((F37-E37)/E37>0,"AMBER","GREEN"))) -> GREEN | H37: One planned circuit day replaced by skidpad session at local airfield (free). Remaining day used for full dynamic envelope exploration. | I37: Continue mixed-venue testing. Formalise airfield agreement with local landowner.
A38: TS | B38: 2 | C38: Circuit hire — Silverstone MIRA test day (1 day, mid-season setup) | D38: Testing & Track Operations | E38: 800 | F38: 800 | G38: =IF(E38=0,"N/A",IF((F38-E38)/E38>0.05,"RED",IF((F38-E38)/E38>0,"AMBER","GREEN"))) -> GREEN | H38: MIRA test day secured via FSAE consortium discount. On budget. | I38: Maintain consortium membership to retain access to discounted circuit testing.
A39: TS | B39: 3 | C39: Tyres — test set (4 × Hoosier R25B, 13-inch) | D39: Testing & Track Operations | E39: 680 | F39: 640 | G39: =IF(E39=0,"N/A",IF((F39-E39)/E39>0.05,"RED",IF((F39-E39)/E39>0,"AMBER","GREEN"))) -> GREEN | H39: Tyre set purchased second-hand from retiring FSAE team. Good condition. | I39: Establish second-hand tyre network via FSAE UK community forum.
A40: TS | B40: 4 | C40: Data logging consumables (SD cards, USB cables, sensor wiring) | D40: Testing & Track Operations | E40: 220 | F40: 195 | G40: =IF(E40=0,"N/A",IF((F40-E40)/E40>0.05,"RED",IF((F40-E40)/E40>0,"AMBER","GREEN"))) -> GREEN | H40: Components sourced via student electronics discount. Minor underspend. | I40: Maintain student discount registrations for electronics suppliers.
...

Sheet Variance Analysis
B1: VARIANCE ANALYSIS — Budget to Actual Decomposition
B2: Category | C2: Budget (£) | D2: Actual (£) | E2: Variance (£) | F2: Var % | G2: Budget Share %
B3: Chassis & Aero Components | C3: =Data!E3 -> 11750 | D3: =Data!F3 -> 14200 | E3: =D3-C3 -> 2450 | F3: =IF(C3=0,0,(D3-C3)/C3) -> 0.20851064 | G3: =IF(Dashboard!C18=0,0,C3/Dashboard!C18) -> 0.30377456
B4: Drivetrain & Suspension | C4: =Data!E9 -> 9200 | D4: =Data!F9 -> 8750 | E4: =D4-C4 -> -450 | F4: =IF(C4=0,0,(D4-C4)/C4) -> -0.048913043 | G4: =IF(Dashboard!C18=0,0,C4/Dashboard!C18) -> 0.23784902
B5: Manufacturing & Workshop | C5: =Data!E16 -> 6800 | D5: =Data!F16 -> 7600 | E5: =D5-C5 -> 800 | F5: =IF(C5=0,0,(D5-C5)/C5) -> 0.11764706 | G5: =IF(Dashboard!C18=0,0,C5/Dashboard!C18) -> 0.17580145
B6: Team Training & Development | C6: =Data!E23 -> 1100 | D6: =Data!F23 -> 1060 | E6: =D6-C6 -> -40 | F6: =IF(C6=0,0,(D6-C6)/C6) -> -0.036363636 | G6: =IF(Dashboard!C18=0,0,C6/Dashboard!C18) -> 0.028438469
B7: Travel & Competition Logistics | C7: =Data!E28 -> 5200 | D7: =Data!F28 -> 5410 | E7: =D7-C7 -> 210 | F7: =IF(C7=0,0,(D7-C7)/C7) -> 0.040384615 | G7: =IF(Dashboard!C18=0,0,C7/Dashboard!C18) -> 0.1344364
B8: Testing & Shakedown | C8: =Data!E36 -> 3380 | D8: =Data!F36 -> 3100 | E8: =D8-C8 -> -280 | F8: =IF(C8=0,0,(D8-C8)/C8) -> -0.082840237 | G8: =IF(Dashboard!C18=0,0,C8/Dashboard!C18) -> 0.087383661
B9: Equipment & Tooling | C9: =Data!E42 -> 1250 | D9: =Data!F42 -> 950 | E9: =D9-C9 -> -300 | F9: =IF(C9=0,0,(D9-C9)/C9) -> -0.24 | G9: =IF(Dashboard!C18=0,0,C9/Dashboard!C18) -> 0.032316443
B10: TOTAL | C10: =SUM(C3:C9) -> 38680 | D10: =SUM(D3:D9) -> 41070 | E10: =D10-C10 -> 2390 | F10: =IF(C10=0,0,(D10-C10)/C10) -> 0.061789038 | G10: =SUM(G3:G9) -> 1
B12: ▸ KEY VARIANCE METRICS
B13: Worst Overspend Category | C13: {=INDEX(B3:B9,MATCH(MAX(E3:E9),E3:E9,0))} -> Chassis & Aero Components
B14: Largest Saving Category | C14: {=INDEX(B3:B9,MATCH(MIN(E3:E9),E3:E9,0))} -> Drivetrain & Suspension
B15: Total Gross Overspend | C15: =SUMIF(E3:E9,">0",E3:E9) -> 3460
B16: Total Gross Savings | C16: =ABS(SUMIF(E3:E9,"<0",E3:E9)) -> 1070
B17: Net Position | C17: =D10-C10 -> 2390
B18: Biggest Overspend % (cats) | C18: =IFERROR(maxifs(F3:F9,F3:F9,">"&0),0) -> 0.20851064

Sheet Assumptions & Notes
B1: ASSUMPTIONS, METHODOLOGY & NOTES
B2: PURPOSE | C2: Portfolio project demonstrating F1-style cost engineering methodology applied to a Formula SAE OBU team. Built to showcase variance analysis, FIA category mapping, and financial reporting skills for motorsport roles.
B3: DATA SOURCE | C3: All figures simulated. Sub-component breakdown reflects simulated Team cost available team reports and competition cost reports.
B4: FIA MAPPING | C4: Seven FIA Financial Regulation Article 2 categories adapted for university scale. Power Unit excluded per FIA convention. Driver compensation excluded (unpaid students). Category RAG auto-calculated from variance % thresholds: >5% = RED, 0–5% = AMBER, ≤0% = GREEN.
B5: TRAINING | C5: Team Training category uses online learning subscriptions (Coursera, Udemy, LinkedIn Learning) to reflect actual course subscription costs.
B6: COLOUR CODE | C6: Blue text = editable input. Black text = formula (do not edit). Yellow/amber = key output. RAG fills: Red/Amber/Green on status cells only.
B7: HOW TO USE | C7: 1. Go to Data sheet. 2. Edit blue cells (Budget, Actual, RAG, Root Cause, Corrective Action) for each sub-component. 3. Category totals update automatically. 4. Dashboard and Variance Analysis recalculate. 5. Do not edit formula cells (black text).
B8: AUTHOR | C8: Wolfgang Guio — MSc Motorsport Engineering (Distinction), Oxford Brookes University. LinkedIn: Wolfgang Guio | GitHub: wguio07
